<?xml version="1.0"?>
<robot name="roki">
  <!-- base_link -->
  <link name="base_link">
    <visual>
      <geometry>
        <cylinder length="0.1" radius="0.15"/>
      </geometry>
      <material name="gray">
        <color rgba="0.5 0.5 0.5 1"/>
      </material>
    </visual>
    <collision>
      <geometry>
        <cylinder length="0.1" radius="0.15"/>
      </geometry>
    </collision>
    <inertial>
      <mass value="10"/>
      <inertia ixx="0.01" ixy="0.0" ixz="0.0" iyy="0.01" iyz="0.0" izz="0.01"/>
    </inertial>
  </link>

  <!-- link_1 -->
  <link name="link_1">
    <visual>
      <geometry>
        <cylinder length="0.33" radius="0.05"/>
      </geometry>
      <origin rpy="0 0 0" xyz="0 0 0.165"/>
      <material name="gold">
        <color rgba="1.0 0.84 0.0 1"/>
      </material>
    </visual>
    <collision>
      <geometry>
        <cylinder length="0.33" radius="0.05"/>
      </geometry>
      <origin rpy="0 0 0" xyz="0 0 0.165"/>
    </collision>
    <inertial>
      <mass value="5"/>
      <inertia ixx="0.01" ixy="0.0" ixz="0.0" iyy="0.01" iyz="0.0" izz="0.01"/>
    </inertial>
  </link>

  <joint name="joint_1" type="revolute">
    <parent link="base_link"/>
    <child link="link_1"/>
    <origin xyz="0 0 0.05" rpy="0 0 0"/>
    <axis xyz="0 0 1"/>
    <limit lower="-3.14" upper="3.14" effort="100" velocity="1.0"/>
  </joint>

  <!-- link_2 -->
  <link name="link_2">
    <visual>
      <geometry>
        <box size="0.05 0.1 0.33"/>
      </geometry>
      <origin rpy="0 0 0" xyz="0.025 0 0.165"/>
      <material name="gold"/>
    </visual>
    <collision>
      <geometry>
        <box size="0.05 0.1 0.33"/>
      </geometry>
      <origin rpy="0 0 0" xyz="0.025 0 0.165"/>
    </collision>
    <inertial>
      <mass value="4"/>
      <inertia ixx="0.01" ixy="0.0" ixz="0.0" iyy="0.01" iyz="0.0" izz="0.01"/>
    </inertial>
  </link>

  <joint name="joint_2" type="revolute">
    <parent link="link_1"/>
    <child link="link_2"/>
    <origin xyz="0.05 0 0.33" rpy="0 0 0"/>
    <axis xyz="0 1 0"/>
    <limit lower="-1.57" upper="1.57" effort="100" velocity="1.0"/>
  </joint>

  <!-- link_3 -->
  <link name="link_3">
    <visual>
      <geometry>
        <cylinder length="0.335" radius="0.04"/>
      </geometry>
      <origin rpy="0 1.5708 0" xyz="0.1675 0 0"/>
      <material name="gold"/>
    </visual>
    <collision>
      <geometry>
        <cylinder length="0.335" radius="0.04"/>
      </geometry>
      <origin rpy="0 1.5708 0" xyz="0.1675 0 0"/>
    </collision>
    <inertial>
      <mass value="3"/>
      <inertia ixx="0.01" ixy="0.0" ixz="0.0" iyy="0.01" iyz="0.0" izz="0.01"/>
    </inertial>
  </link>

  <joint name="joint_3" type="revolute">
    <parent link="link_2"/>
    <child link="link_3"/>
    <origin xyz="0 0 0.33" rpy="0 0 0"/>
    <axis xyz="0 1 0"/>
    <limit lower="-1.57" upper="1.57" effort="100" velocity="1.0"/>
  </joint>

  <!-- link_4 -->
  <link name="link_4">
    <visual>
      <geometry>
        <cylinder length="0.08" radius="0.03"/>
      </geometry>
      <origin rpy="0 1.5708 0" xyz="0.04 0 0"/>
      <material name="gray"/>
    </visual>
    <collision>
      <geometry>
        <cylinder length="0.08" radius="0.03"/>
      </geometry>
      <origin rpy="0 1.5708 0" xyz="0.04 0 0"/>
    </collision>
    <inertial>
      <mass value="1"/>
      <inertia ixx="0.01" ixy="0.0" ixz="0.0" iyy="0.01" iyz="0.0" izz="0.01"/>
    </inertial>
  </link>

  <joint name="joint_4" type="revolute">
    <parent link="link_3"/>
    <child link="link_4"/>
    <origin xyz="0.335 0 0.035" rpy="0 0 0"/>
    <axis xyz="1 0 0"/>
    <limit lower="-3.14" upper="3.14" effort="100" velocity="1.0"/>
  </joint>

  <!-- gripper_link -->
  <link name="gripper_link">
    <visual>
      <geometry>
        <box size="0.05 0.1 0.05"/>
      </geometry>
      <origin rpy="0 0 0" xyz="0.025 0 0"/>
      <material name="black">
        <color rgba="0.1 0.1 0.1 1"/>
      </material>
    </visual>
    <collision>
      <geometry>
        <box size="0.05 0.1 0.05"/>
      </geometry>
      <origin rpy="0 0 0" xyz="0.025 0 0"/>
    </collision>
    <inertial>
      <mass value="0.5"/>
      <inertia ixx="0.01" ixy="0.0" ixz="0.0" iyy="0.01" iyz="0.0" izz="0.01"/>
    </inertial>
  </link>

  <joint name="joint_5" type="revolute">
    <parent link="link_4"/>
    <child link="gripper_link"/>
    <origin xyz="0.08 0 0" rpy="0 0 0"/>
    <axis xyz="0 1 0"/>
    <limit lower="-1.57" upper="1.57" effort="100" velocity="1.0"/>
  </joint>

  <!-- CAMERA SENSOR LINK -->
  <link name="camera_link">
    <visual>
      <geometry>
        <box size="0.02 0.02 0.02"/>
      </geometry>
      <material name="red">
        <color rgba="1 0 0 1"/>
      </material>
    </visual>
  </link>

  <joint name="camera_joint" type="fixed">
    <parent link="gripper_link"/>
    <child link="camera_link"/>
    <origin xyz="0.05 0 0" rpy="0 0 0"/> <!-- Camera at the tip of the gripper -->
  </joint>

  <!-- GAZEBO CAMERA PLUGIN -->
  <gazebo reference="camera_link">
    <sensor type="camera" name="gripper_camera">
      <update_rate>30.0</update_rate>
      <camera name="head">
        <horizontal_fov>1.3962634</horizontal_fov>
        <image>
          <width>800</width>
          <height>600</height>
          <format>R8G8B8</format>
        </image>
        <clip>
          <near>0.02</near>
          <far>300</far>
        </clip>
        <noise>
          <type>gaussian</type>
          <mean>0.0</mean>
          <stddev>0.007</stddev>
        </noise>
      </camera>
      <plugin name="camera_controller" filename="libgazebo_ros_camera.so">
        <alwaysOn>true</alwaysOn>
        <updateRate>0.0</updateRate>
        <cameraName>gripper_camera</cameraName>
        <imageTopicName>image_raw</imageTopicName>
        <cameraInfoTopicName>camera_info</cameraInfoTopicName>
        <frameName>camera_link</frameName>
        <hackBaseline>0.07</hackBaseline>
        <distortionK1>0.0</distortionK1>
        <distortionK2>0.0</distortionK2>
        <distortionK3>0.0</distortionK3>
        <distortionT1>0.0</distortionT1>
        <distortionT2>0.0</distortionT2>
      </plugin>
    </sensor>
    <material>Gazebo/Red</material>
  </gazebo>

  <gazebo reference="link_1">
    <material>Gazebo/Orange</material>
  </gazebo>
  <gazebo reference="link_2">
    <material>Gazebo/Orange</material>
  </gazebo>
  <gazebo reference="link_3">
    <material>Gazebo/Orange</material>
  </gazebo>
  <gazebo reference="base_link">
    <material>Gazebo/Grey</material>
  </gazebo>

  <!-- Ros2 Control or Joint state publisher plugin -->
  <gazebo>
    <plugin name="gazebo_ros_joint_state_publisher" filename="libgazebo_ros_joint_state_publisher.so">
      <update_rate>20</update_rate>
      <joint_name>joint_1</joint_name>
      <joint_name>joint_2</joint_name>
      <joint_name>joint_3</joint_name>
      <joint_name>joint_4</joint_name>
      <joint_name>joint_5</joint_name>
    </plugin>
  </gazebo>
</robot>
